<robot name = "robot">
    <link name="Hips">
        <inertial>
            <origin xyz="0.0 0.0 4.0" rpy="0 0 0"/>
            <mass value="2.5" />
            <inertia ixx="100" ixy="0" ixz="0" iyy="100" iyz="0" izz="100" />
        </inertial>
        <visual>
            <origin xyz="0.0 0.0 4.0" rpy="0 0 0"/>
            <geometry>
                <box size="0.8 1.0 0.5" />
            </geometry>
            <material name="Cyan">
                <color rgba="0 1.0 1.0 1.0"/>
            </material>
        </visual>
        <collision>
            <origin xyz="0.0 0.0 4.0" rpy="0 0 0"/>
            <geometry>
                <box size="0.8 1.0 0.5" />
            </geometry>
        </collision>
    </link>
    <joint name="Hips_LeftLeg" type="revolute">
       <parent link="Hips"/>
       <child  link="LeftLeg"/>
       <origin rpy="0 0 0" xyz="0.0 0.5 4.0" />
     <axis xyz="0 1 0"/>
       <limit effort="0.0" lower="-0.7853981633974483" upper="0.5235987755982988" velocity="0.0"/>
    </joint>
    <link name="LeftLeg">
        <inertial>
            <origin xyz="0.0 0.0 -1.125" rpy="0 0 0"/>
            <mass value="3.5" />
            <inertia ixx="100" ixy="0" ixz="0" iyy="100" iyz="0" izz="100" />
        </inertial>
        <visual>
            <origin xyz="0.0 0.0 -1.125" rpy="0 0 0"/>
            <geometry>
                <box size="0.45 0.45 2.25" />
            </geometry>
            <material name="Cyan">
                <color rgba="0 1.0 1.0 1.0"/>
            </material>
        </visual>
        <collision>
            <origin xyz="0.0 0.0 -1.125" rpy="0 0 0"/>
            <geometry>
                <box size="0.45 0.45 2.25" />
            </geometry>
        </collision>
    </link>
    <joint name="Hips_RightLeg" type="revolute">
       <parent link="Hips"/>
       <child  link="RightLeg"/>
       <origin rpy="0 0 0" xyz="0.0 -0.5 4.0" />
     <axis xyz="0 1 0"/>
       <limit effort="0.0" lower="-0.7853981633974483" upper="0.5235987755982988" velocity="0.0"/>
    </joint>
    <link name="RightLeg">
        <inertial>
            <origin xyz="0.0 0.0 -1.125" rpy="0 0 0"/>
            <mass value="3.5" />
            <inertia ixx="100" ixy="0" ixz="0" iyy="100" iyz="0" izz="100" />
        </inertial>
        <visual>
            <origin xyz="0.0 0.0 -1.125" rpy="0 0 0"/>
            <geometry>
                <box size="0.45 0.45 2.25" />
            </geometry>
            <material name="Cyan">
                <color rgba="0 1.0 1.0 1.0"/>
            </material>
        </visual>
        <collision>
            <origin xyz="0.0 0.0 -1.125" rpy="0 0 0"/>
            <geometry>
                <box size="0.45 0.45 2.25" />
            </geometry>
        </collision>
    </link>
    <joint name="LeftLeg_LeftLowerLeg" type="revolute">
       <parent link="LeftLeg"/>
       <child  link="LeftLowerLeg"/>
       <origin rpy="0 0 0" xyz="0.0 0.0 -2.25" />
     <axis xyz="0 1 0"/>
       <limit effort="0.0" lower="0.0" upper="0.5235987755982988" velocity="0.0"/>
    </joint>
    <link name="LeftLowerLeg">
        <inertial>
            <origin xyz="0.0 0.0 -0.8125" rpy="0 0 0"/>
            <mass value="2.75" />
            <inertia ixx="100" ixy="0" ixz="0" iyy="100" iyz="0" izz="100" />
        </inertial>
        <visual>
            <origin xyz="0.0 0.0 -0.8125" rpy="0 0 0"/>
            <geometry>
                <box size="0.35 0.35 1.625" />
            </geometry>
            <material name="Cyan">
                <color rgba="0 1.0 1.0 1.0"/>
            </material>
        </visual>
        <collision>
            <origin xyz="0.0 0.0 -0.8125" rpy="0 0 0"/>
            <geometry>
                <box size="0.35 0.35 1.625" />
            </geometry>
        </collision>
    </link>
    <joint name="RightLeg_RightLowerLeg" type="revolute">
       <parent link="RightLeg"/>
       <child  link="RightLowerLeg"/>
       <origin rpy="0 0 0" xyz="0.0 0.0 -2.25" />
     <axis xyz="0 1 0"/>
       <limit effort="0.0" lower="0.0" upper="0.5235987755982988" velocity="0.0"/>
    </joint>
    <link name="RightLowerLeg">
        <inertial>
            <origin xyz="0.0 0.0 -0.8125" rpy="0 0 0"/>
            <mass value="2.75" />
            <inertia ixx="100" ixy="0" ixz="0" iyy="100" iyz="0" izz="100" />
        </inertial>
        <visual>
            <origin xyz="0.0 0.0 -0.8125" rpy="0 0 0"/>
            <geometry>
                <box size="0.35 0.35 1.625" />
            </geometry>
            <material name="Cyan">
                <color rgba="0 1.0 1.0 1.0"/>
            </material>
        </visual>
        <collision>
            <origin xyz="0.0 0.0 -0.8125" rpy="0 0 0"/>
            <geometry>
                <box size="0.35 0.35 1.625" />
            </geometry>
        </collision>
    </link>
    <joint name="LeftLowerLeg_LeftFoot" type="revolute">
       <parent link="LeftLowerLeg"/>
       <child  link="LeftFoot"/>
       <origin rpy="0 0 0" xyz="0.0 0.0 -1.625" />
     <axis xyz="0 1 0"/>
       <limit effort="0.0" lower="-0.5235987755982988" upper="0.2617993877991494" velocity="0.0"/>
    </joint>
    <link name="LeftFoot">
        <inertial>
            <origin xyz="0.0 0.0 -0.0625" rpy="0 0 0"/>
            <mass value="1.5" />
            <inertia ixx="100" ixy="0" ixz="0" iyy="100" iyz="0" izz="100" />
        </inertial>
        <visual>
            <origin xyz="0.0 0.0 -0.0625" rpy="0 0 0"/>
            <geometry>
                <box size="0.675 0.675 0.225" />
            </geometry>
            <material name="Cyan">
                <color rgba="0 1.0 1.0 1.0"/>
            </material>
        </visual>
        <collision>
            <origin xyz="0.0 0.0 -0.0625" rpy="0 0 0"/>
            <geometry>
                <box size="0.675 0.675 0.225" />
            </geometry>
        </collision>
    </link>
    <joint name="RightLowerLeg_RightFoot" type="revolute">
       <parent link="RightLowerLeg"/>
       <child  link="RightFoot"/>
       <origin rpy="0 0 0" xyz="0.0 0.0 -1.625" />
     <axis xyz="0 1 0"/>
       <limit effort="0.0" lower="-0.5235987755982988" upper="0.2617993877991494" velocity="0.0"/>
    </joint>
    <link name="RightFoot">
        <inertial>
            <origin xyz="0.0 0.0 -0.0625" rpy="0 0 0"/>
            <mass value="1.5" />
            <inertia ixx="100" ixy="0" ixz="0" iyy="100" iyz="0" izz="100" />
        </inertial>
        <visual>
            <origin xyz="0.0 0.0 -0.0625" rpy="0 0 0"/>
            <geometry>
                <box size="0.675 0.675 0.225" />
            </geometry>
            <material name="Cyan">
                <color rgba="0 1.0 1.0 1.0"/>
            </material>
        </visual>
        <collision>
            <origin xyz="0.0 0.0 -0.0625" rpy="0 0 0"/>
            <geometry>
                <box size="0.675 0.675 0.225" />
            </geometry>
        </collision>
    </link>
    <joint name="Hips_LowerTorso" type="fixed">
       <parent link="Hips"/>
       <child  link="LowerTorso"/>
       <origin rpy="0 0 0" xyz="0.0 0.0 4.25" />
     <axis xyz="0 1 0"/>
       <limit effort="0.0" lower="-0.2617993877991494" upper="0.2617993877991494" velocity="0.0"/>
    </joint>
    <link name="LowerTorso">
        <inertial>
            <origin xyz="0.0 0.0 0.125" rpy="0 0 0"/>
            <mass value="1.0" />
            <inertia ixx="100" ixy="0" ixz="0" iyy="100" iyz="0" izz="100" />
        </inertial>
        <visual>
            <origin xyz="0.0 0.0 0.125" rpy="0 0 0"/>
            <geometry>
                <box size="0.675 0.875 0.25" />
            </geometry>
            <material name="Cyan">
                <color rgba="0 1.0 1.0 1.0"/>
            </material>
        </visual>
        <collision>
            <origin xyz="0.0 0.0 0.125" rpy="0 0 0"/>
            <geometry>
                <box size="0.675 0.875 0.25" />
            </geometry>
        </collision>
    </link>
    <joint name="LowerTorso_MidTorso" type="fixed">
       <parent link="LowerTorso"/>
       <child  link="MidTorso"/>
       <origin rpy="0 0 0" xyz="0.0 0.0 0.25" />
     <axis xyz="0 1 0"/>
       <limit effort="0.0" lower="0.0" upper="0.0" velocity="0.0"/>
    </joint>
    <link name="MidTorso">
        <inertial>
            <origin xyz="0.0 0.0 0.125" rpy="0 0 0"/>
            <mass value="1" />
            <inertia ixx="100" ixy="0" ixz="0" iyy="100" iyz="0" izz="100" />
        </inertial>
        <visual>
            <origin xyz="0.0 0.0 0.125" rpy="0 0 0"/>
            <geometry>
                <box size="0.55 0.75 0.25" />
            </geometry>
            <material name="Cyan">
                <color rgba="0 1.0 1.0 1.0"/>
            </material>
        </visual>
        <collision>
            <origin xyz="0.0 0.0 0.125" rpy="0 0 0"/>
            <geometry>
                <box size="0.55 0.75 0.25" />
            </geometry>
        </collision>
    </link>
</robot>