<robot name = "robot">
    <link name="Torso">
        <inertial>
            <origin xyz="0.0 0.0 4.0" rpy="0 0 0"/>
            <mass value="1" />
            <inertia ixx="100" ixy="0" ixz="0" iyy="100" iyz="0" izz="100" />
        </inertial>
        <visual>
            <origin xyz="0.0 0.0 4.0" rpy="0 0 0"/>
            <geometry>
                <box size="0.8 1.0 0.5" />
            </geometry>
            <material name="Cyan">
                <color rgba="0 1.0 1.0 1.0"/>
            </material>
        </visual>
        <collision>
            <origin xyz="0.0 0.0 4.0" rpy="0 0 0"/>
            <geometry>
                <box size="0.8 1.0 0.5" />
            </geometry>
        </collision>
    </link>
    <joint name="Torso_LeftLeg" type="revolute">
       <parent link="Torso"/>
       <child  link="LeftLeg"/>
       <origin rpy="0 0 0" xyz="0.0 0.5 4.0" />
     <axis xyz="0 1 0"/>
       <limit effort="0.0" lower="0.3926875" upper="-0.3926875" velocity="0.0"/>
    </joint>
    <link name="LeftLeg">
        <inertial>
            <origin xyz="0.0 0.0 -1.125" rpy="0 0 0"/>
            <mass value="1" />
            <inertia ixx="100" ixy="0" ixz="0" iyy="100" iyz="0" izz="100" />
        </inertial>
        <visual>
            <origin xyz="0.0 0.0 -1.125" rpy="0 0 0"/>
            <geometry>
                <box size="0.25 0.25 2.25" />
            </geometry>
            <material name="Cyan">
                <color rgba="0 1.0 1.0 1.0"/>
            </material>
        </visual>
        <collision>
            <origin xyz="0.0 0.0 -1.125" rpy="0 0 0"/>
            <geometry>
                <box size="0.25 0.25 2.25" />
            </geometry>
        </collision>
    </link>
    <joint name="Torso_RightLeg" type="revolute">
       <parent link="Torso"/>
       <child  link="RightLeg"/>
       <origin rpy="0 0 0" xyz="0.0 -0.5 4.0" />
     <axis xyz="0 1 0"/>
       <limit effort="0.0" lower="-0.3926875" upper="0.3926875" velocity="0.0"/>
    </joint>
    <link name="RightLeg">
        <inertial>
            <origin xyz="0.0 0.0 -1.125" rpy="0 0 0"/>
            <mass value="1" />
            <inertia ixx="100" ixy="0" ixz="0" iyy="100" iyz="0" izz="100" />
        </inertial>
        <visual>
            <origin xyz="0.0 0.0 -1.125" rpy="0 0 0"/>
            <geometry>
                <box size="0.25 0.25 2.25" />
            </geometry>
            <material name="Cyan">
                <color rgba="0 1.0 1.0 1.0"/>
            </material>
        </visual>
        <collision>
            <origin xyz="0.0 0.0 -1.125" rpy="0 0 0"/>
            <geometry>
                <box size="0.25 0.25 2.25" />
            </geometry>
        </collision>
    </link>
    <joint name="LeftLeg_LeftLowerLeg" type="revolute">
       <parent link="LeftLeg"/>
       <child  link="LeftLowerLeg"/>
       <origin rpy="0 0 0" xyz="0.0 0.0 -2.25" />
     <axis xyz="0 1 0"/>
       <limit effort="0.0" lower="0.0" upper="0.785375" velocity="0.0"/>
    </joint>
    <link name="LeftLowerLeg">
        <inertial>
            <origin xyz="0.0 0.0 -0.8125" rpy="0 0 0"/>
            <mass value="1" />
            <inertia ixx="100" ixy="0" ixz="0" iyy="100" iyz="0" izz="100" />
        </inertial>
        <visual>
            <origin xyz="0.0 0.0 -0.8125" rpy="0 0 0"/>
            <geometry>
                <box size="0.25 0.25 1.625" />
            </geometry>
            <material name="Cyan">
                <color rgba="0 1.0 1.0 1.0"/>
            </material>
        </visual>
        <collision>
            <origin xyz="0.0 0.0 -0.8125" rpy="0 0 0"/>
            <geometry>
                <box size="0.25 0.25 1.625" />
            </geometry>
        </collision>
    </link>
    <joint name="RightLeg_RightLowerLeg" type="revolute">
       <parent link="RightLeg"/>
       <child  link="RightLowerLeg"/>
       <origin rpy="0 0 0" xyz="0.0 0.0 -2.25" />
     <axis xyz="0 1 0"/>
       <limit effort="0.0" lower="0.0" upper="0.785375" velocity="0.0"/>
    </joint>
    <link name="RightLowerLeg">
        <inertial>
            <origin xyz="0.0 0.0 -0.8125" rpy="0 0 0"/>
            <mass value="1" />
            <inertia ixx="100" ixy="0" ixz="0" iyy="100" iyz="0" izz="100" />
        </inertial>
        <visual>
            <origin xyz="0.0 0.0 -0.8125" rpy="0 0 0"/>
            <geometry>
                <box size="0.25 0.25 1.625" />
            </geometry>
            <material name="Cyan">
                <color rgba="0 1.0 1.0 1.0"/>
            </material>
        </visual>
        <collision>
            <origin xyz="0.0 0.0 -0.8125" rpy="0 0 0"/>
            <geometry>
                <box size="0.25 0.25 1.625" />
            </geometry>
        </collision>
    </link>
    <joint name="LeftLowerLeg_LeftFoot" type="revolute">
       <parent link="LeftLowerLeg"/>
       <child  link="LeftFoot"/>
       <origin rpy="0 0 0" xyz="0.0 0.0 -1.625" />
     <axis xyz="0 1 0"/>
       <limit effort="0.0" lower="-0.785375" upper="1.57075" velocity="0.0"/>
    </joint>
    <link name="LeftFoot">
        <inertial>
            <origin xyz="0.0 0.0 -0.0625" rpy="0 0 0"/>
            <mass value="1" />
            <inertia ixx="100" ixy="0" ixz="0" iyy="100" iyz="0" izz="100" />
        </inertial>
        <visual>
            <origin xyz="0.0 0.0 -0.0625" rpy="0 0 0"/>
            <geometry>
                <box size="0.475 0.475 0.125" />
            </geometry>
            <material name="Cyan">
                <color rgba="0 1.0 1.0 1.0"/>
            </material>
        </visual>
        <collision>
            <origin xyz="0.0 0.0 -0.0625" rpy="0 0 0"/>
            <geometry>
                <box size="0.475 0.475 0.125" />
            </geometry>
        </collision>
    </link>
    <joint name="RightLowerLeg_RightFoot" type="revolute">
       <parent link="RightLowerLeg"/>
       <child  link="RightFoot"/>
       <origin rpy="0 0 0" xyz="0.0 0.0 -1.625" />
     <axis xyz="0 1 0"/>
       <limit effort="0.0" lower="-0.785375" upper="1.57075" velocity="0.0"/>
    </joint>
    <link name="RightFoot">
        <inertial>
            <origin xyz="0.0 0.0 -0.0625" rpy="0 0 0"/>
            <mass value="1" />
            <inertia ixx="100" ixy="0" ixz="0" iyy="100" iyz="0" izz="100" />
        </inertial>
        <visual>
            <origin xyz="0.0 0.0 -0.0625" rpy="0 0 0"/>
            <geometry>
                <box size="0.475 0.475 0.125" />
            </geometry>
            <material name="Cyan">
                <color rgba="0 1.0 1.0 1.0"/>
            </material>
        </visual>
        <collision>
            <origin xyz="0.0 0.0 -0.0625" rpy="0 0 0"/>
            <geometry>
                <box size="0.475 0.475 0.125" />
            </geometry>
        </collision>
    </link>
</robot>